Workbook

Sheet Instructions
B2: Lighting Solutions - Sales Tracker
B3: Automated tracking for the Infrastructure and Building verticals
B5: HOW IT WORKS
B6: 1. Settings | C6: Set your currency label, fiscal-year start month, product categories, sales reps and status rules. Edit only the yellow cells.
B7: 2. Targets | C7: Enter monthly sales targets for each vertical (yellow cells) for every financial year.
B8: 3. Sales_Log | C8: Add one row per invoice / order line. Fill the yellow columns only; grey columns calculate automatically. Use the drop-downs for Vertical, Category, Sales Rep and Status.
B9: 4. Dashboard | C9: Pick the Financial Year in cell C4. All KPIs, tables and charts update automatically.
B11: COLOUR LEGEND
B12: Yellow cell / blue text | C12: Input - type here
B13: Grey cell / black text | C13: Formula - do not overwrite
B14: Green text | C14: Value pulled from another sheet
B16: RULES
B17: Sales counted | C17: Only rows whose Status is flagged 'Yes' under 'Counts as Sale?' in Settings (default: Invoiced, Paid) are counted as sales.
B18: Pipeline | C18: Rows flagged 'Yes' under 'Counts as Pipeline?' (default: Quotation, Order Confirmed) show as open pipeline.
B19: Net Sales | C19: Qty x Unit Price x (1 - Discount %). Amounts exclude tax - enter prices without VAT/tax.
B20: Gross margin | C20: Enter Unit Cost on every row. Rows without a cost add to sales but not to gross profit, which understates the margin %.
B21: Financial Year | C21: Named by the calendar year in which it ends. With a start month of 1 (January), FY2026 = Jan-Dec 2026. With 4 (April), FY2027 = Apr 2026 - Mar 2027.
B22: Capacity | C22: Sales_Log holds 2,000 rows with formulas ready. Row 5 is an EXAMPLE - overwrite or delete its contents before real use.

Sheet Dashboard
B2: =Settings!$C$7&" - Sales Dashboard (FY"&$C$4&", amounts in "&Currency&")" -> Lighting Solutions - Sales Dashboard (FY2026, amounts in USD)
B4: Financial Year | C4: 2026 | D4: <- choose the year; everything below updates
B6: Total Sales | C6: Infrastructure | D6: Building | E6: Annual Target | F6: Achievement | G6: Gross Profit | H6: Gross Margin | I6: Open Pipeline
B7: =SUMIFS(Sales_Log!$K$5:$K$2004,Sales_Log!$S$5:$S$2004,$C$4,Sales_Log!$V$5:$V$2004,"Yes") -> 21090 | C7: =SUMIFS(Sales_Log!$K$5:$K$2004,Sales_Log!$S$5:$S$2004,$C$4,Sales_Log!$V$5:$V$2004,"Yes",Sales_Log!$E$5:$E$2004,"Infrastructure") -> 21090 | D7: =SUMIFS(Sales_Log!$K$5:$K$2004,Sales_Log!$S$5:$S$2004,$C$4,Sales_Log!$V$5:$V$2004,"Yes",Sales_Log!$E$5:$E$2004,"Building") -> 0 | E7: =SUMIFS(Targets!$G$6:$G$47,Targets!$B$6:$B$47,$C$4,Targets!$C$6:$C$47,">0") -> 0 | F7: =IF(E7=0,"",B7/E7) | G7: =SUMIFS(Sales_Log!$N$5:$N$2004,Sales_Log!$S$5:$S$2004,$C$4,Sales_Log!$V$5:$V$2004,"Yes") -> 6690 | H7: =IF(B7=0,"",G7/B7) -> 0.31721195 | I7: =SUMIFS(Sales_Log!$K$5:$K$2004,Sales_Log!$S$5:$S$2004,$C$4,Sales_Log!$W$5:$W$2004,"Yes") -> 0
B9: Monthly Performance
A10: # | B10: Month | C10: Infra Sales | D10: Infra Target | E10: Infra Ach % | F10: Building Sales | G10: Building Target | H10: Building Ach % | I10: Total Sales | J10: Total Target | K10: Ach % | L10: Cumulative Sales | M10: Cumulative Target
A11: 1 | B11: =TEXT(DATE(2000,FYStart+A11-1,1),"mmm") -> Jan | C11: =SUMIFS(Sales_Log!$K$5:$K$2004,Sales_Log!$S$5:$S$2004,$C$4,Sales_Log!$V$5:$V$2004,"Yes",Sales_Log!$T$5:$T$2004,$A11,Sales_Log!$E$5:$E$2004,"Infrastructure") -> 0 | D11: =SUMIFS(Targets!$E$6:$E$47,Targets!$B$6:$B$47,$C$4,Targets!$C$6:$C$47,$A11) -> 0 | E11: =IF(D11=0,"",C11/D11) | F11: =SUMIFS(Sales_Log!$K$5:$K$2004,Sales_Log!$S$5:$S$2004,$C$4,Sales_Log!$V$5:$V$2004,"Yes",Sales_Log!$T$5:$T$2004,$A11,Sales_Log!$E$5:$E$2004,"Building") -> 0 | G11: =SUMIFS(Targets!$F$6:$F$47,Targets!$B$6:$B$47,$C$4,Targets!$C$6:$C$47,$A11) -> 0 | H11: =IF(G11=0,"",F11/G11) | I11: =C11+F11 -> 0 | J11: =D11+G11 -> 0 | K11: =IF(J11=0,"",I11/J11) | L11: =SUM($I$11:I11) -> 0 | M11: =SUM($J$11:J11) -> 0
A12: 2 | B12: =TEXT(DATE(2000,FYStart+A12-1,1),"mmm") -> Feb | C12: =SUMIFS(Sales_Log!$K$5:$K$2004,Sales_Log!$S$5:$S$2004,$C$4,Sales_Log!$V$5:$V$2004,"Yes",Sales_Log!$T$5:$T$2004,$A12,Sales_Log!$E$5:$E$2004,"Infrastructure") -> 0 | D12: =SUMIFS(Targets!$E$6:$E$47,Targets!$B$6:$B$47,$C$4,Targets!$C$6:$C$47,$A12) -> 0 | E12: =IF(D12=0,"",C12/D12) | F12: =SUMIFS(Sales_Log!$K$5:$K$2004,Sales_Log!$S$5:$S$2004,$C$4,Sales_Log!$V$5:$V$2004,"Yes",Sales_Log!$T$5:$T$2004,$A12,Sales_Log!$E$5:$E$2004,"Building") -> 0 | G12: =SUMIFS(Targets!$F$6:$F$47,Targets!$B$6:$B$47,$C$4,Targets!$C$6:$C$47,$A12) -> 0 | H12: =IF(G12=0,"",F12/G12) | I12: =C12+F12 -> 0 | J12: =D12+G12 -> 0 | K12: =IF(J12=0,"",I12/J12) | L12: =SUM($I$11:I12) -> 0 | M12: =SUM($J$11:J12) -> 0
A13: 3 | B13: =TEXT(DATE(2000,FYStart+A13-1,1),"mmm") -> Mar | C13: =SUMIFS(Sales_Log!$K$5:$K$2004,Sales_Log!$S$5:$S$2004,$C$4,Sales_Log!$V$5:$V$2004,"Yes",Sales_Log!$T$5:$T$2004,$A13,Sales_Log!$E$5:$E$2004,"Infrastructure") -> 0 | D13: =SUMIFS(Targets!$E$6:$E$47,Targets!$B$6:$B$47,$C$4,Targets!$C$6:$C$47,$A13) -> 0 | E13: =IF(D13=0,"",C13/D13) | F13: =SUMIFS(Sales_Log!$K$5:$K$2004,Sales_Log!$S$5:$S$2004,$C$4,Sales_Log!$V$5:$V$2004,"Yes",Sales_Log!$T$5:$T$2004,$A13,Sales_Log!$E$5:$E$2004,"Building") -> 0 | G13: =SUMIFS(Targets!$F$6:$F$47,Targets!$B$6:$B$47,$C$4,Targets!$C$6:$C$47,$A13) -> 0 | H13: =IF(G13=0,"",F13/G13) | I13: =C13+F13 -> 0 | J13: =D13+G13 -> 0 | K13: =IF(J13=0,"",I13/J13) | L13: =SUM($I$11:I13) -> 0 | M13: =SUM($J$11:J13) -> 0
A14: 4 | B14: =TEXT(DATE(2000,FYStart+A14-1,1),"mmm") -> Apr | C14: =SUMIFS(Sales_Log!$K$5:$K$2004,Sales_Log!$S$5:$S$2004,$C$4,Sales_Log!$V$5:$V$2004,"Yes",Sales_Log!$T$5:$T$2004,$A14,Sales_Log!$E$5:$E$2004,"Infrastructure") -> 0 | D14: =SUMIFS(Targets!$E$6:$E$47,Targets!$B$6:$B$47,$C$4,Targets!$C$6:$C$47,$A14) -> 0 | E14: =IF(D14=0,"",C14/D14) | F14: =SUMIFS(Sales_Log!$K$5:$K$2004,Sales_Log!$S$5:$S$2004,$C$4,Sales_Log!$V$5:$V$2004,"Yes",Sales_Log!$T$5:$T$2004,$A14,Sales_Log!$E$5:$E$2004,"Building") -> 0 | G14: =SUMIFS(Targets!$F$6:$F$47,Targets!$B$6:$B$47,$C$4,Targets!$C$6:$C$47,$A14) -> 0 | H14: =IF(G14=0,"",F14/G14) | I14: =C14+F14 -> 0 | J14: =D14+G14 -> 0 | K14: =IF(J14=0,"",I14/J14) | L14: =SUM($I$11:I14) -> 0 | M14: =SUM($J$11:J14) -> 0
A15: 5 | B15: =TEXT(DATE(2000,FYStart+A15-1,1),"mmm") -> May | C15: =SUMIFS(Sales_Log!$K$5:$K$2004,Sales_Log!$S$5:$S$2004,$C$4,Sales_Log!$V$5:$V$2004,"Yes",Sales_Log!$T$5:$T$2004,$A15,Sales_Log!$E$5:$E$2004,"Infrastructure") -> 0 | D15: =SUMIFS(Targets!$E$6:$E$47,Targets!$B$6:$B$47,$C$4,Targets!$C$6:$C$47,$A15) -> 0 | E15: =IF(D15=0,"",C15/D15) | F15: =SUMIFS(Sales_Log!$K$5:$K$2004,Sales_Log!$S$5:$S$2004,$C$4,Sales_Log!$V$5:$V$2004,"Yes",Sales_Log!$T$5:$T$2004,$A15,Sales_Log!$E$5:$E$2004,"Building") -> 0 | G15: =SUMIFS(Targets!$F$6:$F$47,Targets!$B$6:$B$47,$C$4,Targets!$C$6:$C$47,$A15) -> 0 | H15: =IF(G15=0,"",F15/G15) | I15: =C15+F15 -> 0 | J15: =D15+G15 -> 0 | K15: =IF(J15=0,"",I15/J15) | L15: =SUM($I$11:I15) -> 0 | M15: =SUM($J$11:J15) -> 0
A16: 6 | B16: =TEXT(DATE(2000,FYStart+A16-1,1),"mmm") -> Jun | C16: =SUMIFS(Sales_Log!$K$5:$K$2004,Sales_Log!$S$5:$S$2004,$C$4,Sales_Log!$V$5:$V$2004,"Yes",Sales_Log!$T$5:$T$2004,$A16,Sales_Log!$E$5:$E$2004,"Infrastructure") -> 0 | D16: =SUMIFS(Targets!$E$6:$E$47,Targets!$B$6:$B$47,$C$4,Targets!$C$6:$C$47,$A16) -> 0 | E16: =IF(D16=0,"",C16/D16) | F16: =SUMIFS(Sales_Log!$K$5:$K$2004,Sales_Log!$S$5:$S$2004,$C$4,Sales_Log!$V$5:$V$2004,"Yes",Sales_Log!$T$5:$T$2004,$A16,Sales_Log!$E$5:$E$2004,"Building") -> 0 | G16: =SUMIFS(Targets!$F$6:$F$47,Targets!$B$6:$B$47,$C$4,Targets!$C$6:$C$47,$A16) -> 0 | H16: =IF(G16=0,"",F16/G16) | I16: =C16+F16 -> 0 | J16: =D16+G16 -> 0 | K16: =IF(J16=0,"",I16/J16) | L16: =SUM($I$11:I16) -> 0 | M16: =SUM($J$11:J16) -> 0
A17: 7 | B17: =TEXT(DATE(2000,FYStart+A17-1,1),"mmm") -> Jul | C17: =SUMIFS(Sales_Log!$K$5:$K$2004,Sales_Log!$S$5:$S$2004,$C$4,Sales_Log!$V$5:$V$2004,"Yes",Sales_Log!$T$5:$T$2004,$A17,Sales_Log!$E$5:$E$2004,"Infrastructure") -> 0 | D17: =SUMIFS(Targets!$E$6:$E$47,Targets!$B$6:$B$47,$C$4,Targets!$C$6:$C$47,$A17) -> 0 | E17: =IF(D17=0,"",C17/D17) | F17: =SUMIFS(Sales_Log!$K$5:$K$2004,Sales_Log!$S$5:$S$2004,$C$4,Sales_Log!$V$5:$V$2004,"Yes",Sales_Log!$T$5:$T$2004,$A17,Sales_Log!$E$5:$E$2004,"Building") -> 0 | G17: =SUMIFS(Targets!$F$6:$F$47,Targets!$B$6:$B$47,$C$4,Targets!$C$6:$C$47,$A17) -> 0 | H17: =IF(G17=0,"",F17/G17) | I17: =C17+F17 -> 0 | J17: =D17+G17 -> 0 | K17: =IF(J17=0,"",I17/J17) | L17: =SUM($I$11:I17) -> 0 | M17: =SUM($J$11:J17) -> 0
A18: 8 | B18: =TEXT(DATE(2000,FYStart+A18-1,1),"mmm") -> Aug | C18: =SUMIFS(Sales_Log!$K$5:$K$2004,Sales_Log!$S$5:$S$2004,$C$4,Sales_Log!$V$5:$V$2004,"Yes",Sales_Log!$T$5:$T$2004,$A18,Sales_Log!$E$5:$E$2004,"Infrastructure") -> 0 | D18: =SUMIFS(Targets!$E$6:$E$47,Targets!$B$6:$B$47,$C$4,Targets!$C$6:$C$47,$A18) -> 0 | E18: =IF(D18=0,"",C18/D18) | F18: =SUMIFS(Sales_Log!$K$5:$K$2004,Sales_Log!$S$5:$S$2004,$C$4,Sales_Log!$V$5:$V$2004,"Yes",Sales_Log!$T$5:$T$2004,$A18,Sales_Log!$E$5:$E$2004,"Building") -> 0 | G18: =SUMIFS(Targets!$F$6:$F$47,Targets!$B$6:$B$47,$C$4,Targets!$C$6:$C$47,$A18) -> 0 | H18: =IF(G18=0,"",F18/G18) | I18: =C18+F18 -> 0 | J18: =D18+G18 -> 0 | K18: =IF(J18=0,"",I18/J18) | L18: =SUM($I$11:I18) -> 0 | M18: =SUM($J$11:J18) -> 0
A19: 9 | B19: =TEXT(DATE(2000,FYStart+A19-1,1),"mmm") -> Sep | C19: =SUMIFS(Sales_Log!$K$5:$K$2004,Sales_Log!$S$5:$S$2004,$C$4,Sales_Log!$V$5:$V$2004,"Yes",Sales_Log!$T$5:$T$2004,$A19,Sales_Log!$E$5:$E$2004,"Infrastructure") -> 21090 | D19: =SUMIFS(Targets!$E$6:$E$47,Targets!$B$6:$B$47,$C$4,Targets!$C$6:$C$47,$A19) -> 0 | E19: =IF(D19=0,"",C19/D19) | F19: =SUMIFS(Sales_Log!$K$5:$K$2004,Sales_Log!$S$5:$S$2004,$C$4,Sales_Log!$V$5:$V$2004,"Yes",Sales_Log!$T$5:$T$2004,$A19,Sales_Log!$E$5:$E$2004,"Building") -> 0 | G19: =SUMIFS(Targets!$F$6:$F$47,Targets!$B$6:$B$47,$C$4,Targets!$C$6:$C$47,$A19) -> 0 | H19: =IF(G19=0,"",F19/G19) | I19: =C19+F19 -> 21090 | J19: =D19+G19 -> 0 | K19: =IF(J19=0,"",I19/J19) | L19: =SUM($I$11:I19) -> 21090 | M19: =SUM($J$11:J19) -> 0
A20: 10 | B20: =TEXT(DATE(2000,FYStart+A20-1,1),"mmm") -> Oct | C20: =SUMIFS(Sales_Log!$K$5:$K$2004,Sales_Log!$S$5:$S$2004,$C$4,Sales_Log!$V$5:$V$2004,"Yes",Sales_Log!$T$5:$T$2004,$A20,Sales_Log!$E$5:$E$2004,"Infrastructure") -> 0 | D20: =SUMIFS(Targets!$E$6:$E$47,Targets!$B$6:$B$47,$C$4,Targets!$C$6:$C$47,$A20) -> 0 | E20: =IF(D20=0,"",C20/D20) | F20: =SUMIFS(Sales_Log!$K$5:$K$2004,Sales_Log!$S$5:$S$2004,$C$4,Sales_Log!$V$5:$V$2004,"Yes",Sales_Log!$T$5:$T$2004,$A20,Sales_Log!$E$5:$E$2004,"Building") -> 0 | G20: =SUMIFS(Targets!$F$6:$F$47,Targets!$B$6:$B$47,$C$4,Targets!$C$6:$C$47,$A20) -> 0 | H20: =IF(G20=0,"",F20/G20) | I20: =C20+F20 -> 0 | J20: =D20+G20 -> 0 | K20: =IF(J20=0,"",I20/J20) | L20: =SUM($I$11:I20) -> 21090 | M20: =SUM($J$11:J20) -> 0
A21: 11 | B21: =TEXT(DATE(2000,FYStart+A21-1,1),"mmm") -> Nov | C21: =SUMIFS(Sales_Log!$K$5:$K$2004,Sales_Log!$S$5:$S$2004,$C$4,Sales_Log!$V$5:$V$2004,"Yes",Sales_Log!$T$5:$T$2004,$A21,Sales_Log!$E$5:$E$2004,"Infrastructure") -> 0 | D21: =SUMIFS(Targets!$E$6:$E$47,Targets!$B$6:$B$47,$C$4,Targets!$C$6:$C$47,$A21) -> 0 | E21: =IF(D21=0,"",C21/D21) | F21: =SUMIFS(Sales_Log!$K$5:$K$2004,Sales_Log!$S$5:$S$2004,$C$4,Sales_Log!$V$5:$V$2004,"Yes",Sales_Log!$T$5:$T$2004,$A21,Sales_Log!$E$5:$E$2004,"Building") -> 0 | G21: =SUMIFS(Targets!$F$6:$F$47,Targets!$B$6:$B$47,$C$4,Targets!$C$6:$C$47,$A21) -> 0 | H21: =IF(G21=0,"",F21/G21) | I21: =C21+F21 -> 0 | J21: =D21+G21 -> 0 | K21: =IF(J21=0,"",I21/J21) | L21: =SUM($I$11:I21) -> 21090 | M21: =SUM($J$11:J21) -> 0
A22: 12 | B22: =TEXT(DATE(2000,FYStart+A22-1,1),"mmm") -> Dec | C22: =SUMIFS(Sales_Log!$K$5:$K$2004,Sales_Log!$S$5:$S$2004,$C$4,Sales_Log!$V$5:$V$2004,"Yes",Sales_Log!$T$5:$T$2004,$A22,Sales_Log!$E$5:$E$2004,"Infrastructure") -> 0 | D22: =SUMIFS(Targets!$E$6:$E$47,Targets!$B$6:$B$47,$C$4,Targets!$C$6:$C$47,$A22) -> 0 | E22: =IF(D22=0,"",C22/D22) | F22: =SUMIFS(Sales_Log!$K$5:$K$2004,Sales_Log!$S$5:$S$2004,$C$4,Sales_Log!$V$5:$V$2004,"Yes",Sales_Log!$T$5:$T$2004,$A22,Sales_Log!$E$5:$E$2004,"Building") -> 0 | G22: =SUMIFS(Targets!$F$6:$F$47,Targets!$B$6:$B$47,$C$4,Targets!$C$6:$C$47,$A22) -> 0 | H22: =IF(G22=0,"",F22/G22) | I22: =C22+F22 -> 0 | J22: =D22+G22 -> 0 | K22: =IF(J22=0,"",I22/J22) | L22: =SUM($I$11:I22) -> 21090 | M22: =SUM($J$11:J22) -> 0
B23: Total | C23: =SUM(C11:C22) -> 21090 | D23: =SUM(D11:D22) -> 0 | E23: =IF(D23=0,"",C23/D23) | F23: =SUM(F11:F22) -> 0 | G23: =SUM(G11:G22) -> 0 | H23: =IF(G23=0,"",F23/G23) | I23: =SUM(I11:I22) -> 21090 | J23: =SUM(J11:J22) -> 0 | K23: =IF(J23=0,"",I23/J23)
B25: Sales by Product Category | J25: Deals by Status
B26: Product Category | C26: Infrastructure | D26: Building | E26: Total | F26: Share % | G26: Gross Profit | H26: GM % | J26: Status | K26: No. of Lines | L26: Infrastructure | M26: Building | N26: Total
B27: =IF(Settings!$D$11="","",Settings!$D$11) -> Street Lighting | C27: =IF($B27="","",SUMIFS(Sales_Log!$K$5:$K$2004,Sales_Log!$S$5:$S$2004,$C$4,Sales_Log!$V$5:$V$2004,"Yes",Sales_Log!$F$5:$F$2004,$B27,Sales_Log!$E$5:$E$2004,"Infrastructure")) -> 21090 | D27: =IF($B27="","",SUMIFS(Sales_Log!$K$5:$K$2004,Sales_Log!$S$5:$S$2004,$C$4,Sales_Log!$V$5:$V$2004,"Yes",Sales_Log!$F$5:$F$2004,$B27,Sales_Log!$E$5:$E$2004,"Building")) -> 0 | E27: =IF($B27="","",N(C27)+N(D27)) -> 21090 | F27: =IF(OR($B27="",$E$42=0),"",E27/$E$42) -> 1 | G27: =IF($B27="","",SUMIFS(Sales_Log!$N$5:$N$2004,Sales_Log!$S$5:$S$2004,$C$4,Sales_Log!$V$5:$V$2004,"Yes",Sales_Log!$F$5:$F$2004,$B27)) -> 6690 | H27: =IF(OR($B27="",N(E27)=0),"",G27/E27) -> 0.31721195 | J27: =Settings!$H$11 -> Quotation | K27: =COUNTIFS(Sales_Log!$S$5:$S$2004,$C$4,Sales_Log!$Q$5:$Q$2004,$J27) -> 0 | L27: =SUMIFS(Sales_Log!$K$5:$K$2004,Sales_Log!$S$5:$S$2004,$C$4,Sales_Log!$Q$5:$Q$2004,$J27,Sales_Log!$E$5:$E$2004,"Infrastructure") -> 0 | M27: =SUMIFS(Sales_Log!$K$5:$K$2004,Sales_Log!$S$5:$S$2004,$C$4,Sales_Log!$Q$5:$Q$2004,$J27,Sales_Log!$E$5:$E$2004,"Building") -> 0 | N27: =L27+M27 -> 0
B28: =IF(Settings!$D$12="","",Settings!$D$12) -> Floodlighting | C28: =IF($B28="","",SUMIFS(Sales_Log!$K$5:$K$2004,Sales_Log!$S$5:$S$2004,$C$4,Sales_Log!$V$5:$V$2004,"Yes",Sales_Log!$F$5:$F$2004,$B28,Sales_Log!$E$5:$E$2004,"Infrastructure")) -> 0 | D28: =IF($B28="","",SUMIFS(Sales_Log!$K$5:$K$2004,Sales_Log!$S$5:$S$2004,$C$4,Sales_Log!$V$5:$V$2004,"Yes",Sales_Log!$F$5:$F$2004,$B28,Sales_Log!$E$5:$E$2004,"Building")) -> 0 | E28: =IF($B28="","",N(C28)+N(D28)) -> 0 | F28: =IF(OR($B28="",$E$42=0),"",E28/$E$42) -> 0 | G28: =IF($B28="","",SUMIFS(Sales_Log!$N$5:$N$2004,Sales_Log!$S$5:$S$2004,$C$4,Sales_Log!$V$5:$V$2004,"Yes",Sales_Log!$F$5:$F$2004,$B28)) -> 0 | H28: =IF(OR($B28="",N(E28)=0),"",G28/E28) | J28: =Settings!$H$12 -> Order Confirmed | K28: =COUNTIFS(Sales_Log!$S$5:$S$2004,$C$4,Sales_Log!$Q$5:$Q$2004,$J28) -> 0 | L28: =SUMIFS(Sales_Log!$K$5:$K$2004,Sales_Log!$S$5:$S$2004,$C$4,Sales_Log!$Q$5:$Q$2004,$J28,Sales_Log!$E$5:$E$2004,"Infrastructure") -> 0 | M28: =SUMIFS(Sales_Log!$K$5:$K$2004,Sales_Log!$S$5:$S$2004,$C$4,Sales_Log!$Q$5:$Q$2004,$J28,Sales_Log!$E$5:$E$2004,"Building") -> 0 | N28: =L28+M28 -> 0
B29: =IF(Settings!$D$13="","",Settings!$D$13) -> High Mast | C29: =IF($B29="","",SUMIFS(Sales_Log!$K$5:$K$2004,Sales_Log!$S$5:$S$2004,$C$4,Sales_Log!$V$5:$V$2004,"Yes",Sales_Log!$F$5:$F$2004,$B29,Sales_Log!$E$5:$E$2004,"Infrastructure")) -> 0 | D29: =IF($B29="","",SUMIFS(Sales_Log!$K$5:$K$2004,Sales_Log!$S$5:$S$2004,$C$4,Sales_Log!$V$5:$V$2004,"Yes",Sales_Log!$F$5:$F$2004,$B29,Sales_Log!$E$5:$E$2004,"Building")) -> 0 | E29: =IF($B29="","",N(C29)+N(D29)) -> 0 | F29: =IF(OR($B29="",$E$42=0),"",E29/$E$42) -> 0 | G29: =IF($B29="","",SUMIFS(Sales_Log!$N$5:$N$2004,Sales_Log!$S$5:$S$2004,$C$4,Sales_Log!$V$5:$V$2004,"Yes",Sales_Log!$F$5:$F$2004,$B29)) -> 0 | H29: =IF(OR($B29="",N(E29)=0),"",G29/E29) | J29: =Settings!$H$13 -> Invoiced | K29: =COUNTIFS(Sales_Log!$S$5:$S$2004,$C$4,Sales_Log!$Q$5:$Q$2004,$J29) -> 1 | L29: =SUMIFS(Sales_Log!$K$5:$K$2004,Sales_Log!$S$5:$S$2004,$C$4,Sales_Log!$Q$5:$Q$2004,$J29,Sales_Log!$E$5:$E$2004,"Infrastructure") -> 21090 | M29: =SUMIFS(Sales_Log!$K$5:$K$2004,Sales_Log!$S$5:$S$2004,$C$4,Sales_Log!$Q$5:$Q$2004,$J29,Sales_Log!$E$5:$E$2004,"Building") -> 0 | N29: =L29+M29 -> 21090
B30: =IF(Settings!$D$14="","",Settings!$D$14) -> Tunnel Lighting | C30: =IF($B30="","",SUMIFS(Sales_Log!$K$5:$K$2004,Sales_Log!$S$5:$S$2004,$C$4,Sales_Log!$V$5:$V$2004,"Yes",Sales_Log!$F$5:$F$2004,$B30,Sales_Log!$E$5:$E$2004,"Infrastructure")) -> 0 | D30: =IF($B30="","",SUMIFS(Sales_Log!$K$5:$K$2004,Sales_Log!$S$5:$S$2004,$C$4,Sales_Log!$V$5:$V$2004,"Yes",Sales_Log!$F$5:$F$2004,$B30,Sales_Log!$E$5:$E$2004,"Building")) -> 0 | E30: =IF($B30="","",N(C30)+N(D30)) -> 0 | F30: =IF(OR($B30="",$E$42=0),"",E30/$E$42) -> 0 | G30: =IF($B30="","",SUMIFS(Sales_Log!$N$5:$N$2004,Sales_Log!$S$5:$S$2004,$C$4,Sales_Log!$V$5:$V$2004,"Yes",Sales_Log!$F$5:$F$2004,$B30)) -> 0 | H30: =IF(OR($B30="",N(E30)=0),"",G30/E30) | J30: =Settings!$H$14 -> Paid | K30: =COUNTIFS(Sales_Log!$S$5:$S$2004,$C$4,Sales_Log!$Q$5:$Q$2004,$J30) -> 0 | L30: =SUMIFS(Sales_Log!$K$5:$K$2004,Sales_Log!$S$5:$S$2004,$C$4,Sales_Log!$Q$5:$Q$2004,$J30,Sales_Log!$E$5:$E$2004,"Infrastructure") -> 0 | M30: =SUMIFS(Sales_Log!$K$5:$K$2004,Sales_Log!$S$5:$S$2004,$C$4,Sales_Log!$Q$5:$Q$2004,$J30,Sales_Log!$E$5:$E$2004,"Building") -> 0 | N30: =L30+M30 -> 0
B31: =IF(Settings!$D$15="","",Settings!$D$15) -> Solar Lighting | C31: =IF($B31="","",SUMIFS(Sales_Log!$K$5:$K$2004,Sales_Log!$S$5:$S$2004,$C$4,Sales_Log!$V$5:$V$2004,"Yes",Sales_Log!$F$5:$F$2004,$B31,Sales_Log!$E$5:$E$2004,"Infrastructure")) -> 0 | D31: =IF($B31="","",SUMIFS(Sales_Log!$K$5:$K$2004,Sales_Log!$S$5:$S$2004,$C$4,Sales_Log!$V$5:$V$2004,"Yes",Sales_Log!$F$5:$F$2004,$B31,Sales_Log!$E$5:$E$2004,"Building")) -> 0 | E31: =IF($B31="","",N(C31)+N(D31)) -> 0 | F31: =IF(OR($B31="",$E$42=0),"",E31/$E$42) -> 0 | G31: =IF($B31="","",SUMIFS(Sales_Log!$N$5:$N$2004,Sales_Log!$S$5:$S$2004,$C$4,Sales_Log!$V$5:$V$2004,"Yes",Sales_Log!$F$5:$F$2004,$B31)) -> 0 | H31: =IF(OR($B31="",N(E31)=0),"",G31/E31) | J31: =Settings!$H$15 -> Lost | K31: =COUNTIFS(Sales_Log!$S$5:$S$2004,$C$4,Sales_Log!$Q$5:$Q$2004,$J31) -> 0 | L31: =SUMIFS(Sales_Log!$K$5:$K$2004,Sales_Log!$S$5:$S$2004,$C$4,Sales_Log!$Q$5:$Q$2004,$J31,Sales_Log!$E$5:$E$2004,"Infrastructure") -> 0 | M31: =SUMIFS(Sales_Log!$K$5:$K$2004,Sales_Log!$S$5:$S$2004,$C$4,Sales_Log!$Q$5:$Q$2004,$J31,Sales_Log!$E$5:$E$2004,"Building") -> 0 | N31: =L31+M31 -> 0
B32: =IF(Settings!$D$16="","",Settings!$D$16) -> Indoor Commercial | C32: =IF($B32="","",SUMIFS(Sales_Log!$K$5:$K$2004,Sales_Log!$S$5:$S$2004,$C$4,Sales_Log!$V$5:$V$2004,"Yes",Sales_Log!$F$5:$F$2004,$B32,Sales_Log!$E$5:$E$2004,"Infrastructure")) -> 0 | D32: =IF($B32="","",SUMIFS(Sales_Log!$K$5:$K$2004,Sales_Log!$S$5:$S$2004,$C$4,Sales_Log!$V$5:$V$2004,"Yes",Sales_Log!$F$5:$F$2004,$B32,Sales_Log!$E$5:$E$2004,"Building")) -> 0 | E32: =IF($B32="","",N(C32)+N(D32)) -> 0 | F32: =IF(OR($B32="",$E$42=0),"",E32/$E$42) -> 0 | G32: =IF($B32="","",SUMIFS(Sales_Log!$N$5:$N$2004,Sales_Log!$S$5:$S$2004,$C$4,Sales_Log!$V$5:$V$2004,"Yes",Sales_Log!$F$5:$F$2004,$B32)) -> 0 | H32: =IF(OR($B32="",N(E32)=0),"",G32/E32) | J32: Win rate (value) | N32: =IF(($B$7+SUMIFS(Sales_Log!$K$5:$K$2004,Sales_Log!$S$5:$S$2004,$C$4,Sales_Log!$Q$5:$Q$2004,"Lost"))=0,"",$B$7/($B$7+SUMIFS(Sales_Log!$K$5:$K$2004,Sales_Log!$S$5:$S$2004,$C$4,Sales_Log!$Q$5:$Q$2004,"Lost"))) -> 1
B33: =IF(Settings!$D$17="","",Settings!$D$17) -> Industrial / High Bay | C33: =IF($B33="","",SUMIFS(Sales_Log!$K$5:$K$2004,Sales_Log!$S$5:$S$2004,$C$4,Sales_Log!$V$5:$V$2004,"Yes",Sales_Log!$F$5:$F$2004,$B33,Sales_Log!$E$5:$E$2004,"Infrastructure")) -> 0 | D33: =IF($B33="","",SUMIFS(Sales_Log!$K$5:$K$2004,Sales_Log!$S$5:$S$2004,$C$4,Sales_Log!$V$5:$V$2004,"Yes",Sales_Log!$F$5:$F$2004,$B33,Sales_Log!$E$5:$E$2004,"Building")) -> 0 | E33: =IF($B33="","",N(C33)+N(D33)) -> 0 | F33: =IF(OR($B33="",$E$42=0),"",E33/$E$42) -> 0 | G33: =IF($B33="","",SUMIFS(Sales_Log!$N$5:$N$2004,Sales_Log!$S$5:$S$2004,$C$4,Sales_Log!$V$5:$V$2004,"Yes",Sales_Log!$F$5:$F$2004,$B33)) -> 0 | H33: =IF(OR($B33="",N(E33)=0),"",G33/E33)
B34: =IF(Settings!$D$18="","",Settings!$D$18) -> Architectural / Facade | C34: =IF($B34="","",SUMIFS(Sales_Log!$K$5:$K$2004,Sales_Log!$S$5:$S$2004,$C$4,Sales_Log!$V$5:$V$2004,"Yes",Sales_Log!$F$5:$F$2004,$B34,Sales_Log!$E$5:$E$2004,"Infrastructure")) -> 0 | D34: =IF($B34="","",SUMIFS(Sales_Log!$K$5:$K$2004,Sales_Log!$S$5:$S$2004,$C$4,Sales_Log!$V$5:$V$2004,"Yes",Sales_Log!$F$5:$F$2004,$B34,Sales_Log!$E$5:$E$2004,"Building")) -> 0 | E34: =IF($B34="","",N(C34)+N(D34)) -> 0 | F34: =IF(OR($B34="",$E$42=0),"",E34/$E$42) -> 0 | G34: =IF($B34="","",SUMIFS(Sales_Log!$N$5:$N$2004,Sales_Log!$S$5:$S$2004,$C$4,Sales_Log!$V$5:$V$2004,"Yes",Sales_Log!$F$5:$F$2004,$B34)) -> 0 | H34: =IF(OR($B34="",N(E34)=0),"",G34/E34) | J34: Vertical Share
B35: =IF(Settings!$D$19="","",Settings!$D$19) -> Emergency & Exit | C35: =IF($B35="","",SUMIFS(Sales_Log!$K$5:$K$2004,Sales_Log!$S$5:$S$2004,$C$4,Sales_Log!$V$5:$V$2004,"Yes",Sales_Log!$F$5:$F$2004,$B35,Sales_Log!$E$5:$E$2004,"Infrastructure")) -> 0 | D35: =IF($B35="","",SUMIFS(Sales_Log!$K$5:$K$2004,Sales_Log!$S$5:$S$2004,$C$4,Sales_Log!$V$5:$V$2004,"Yes",Sales_Log!$F$5:$F$2004,$B35,Sales_Log!$E$5:$E$2004,"Building")) -> 0 | E35: =IF($B35="","",N(C35)+N(D35)) -> 0 | F35: =IF(OR($B35="",$E$42=0),"",E35/$E$42) -> 0 | G35: =IF($B35="","",SUMIFS(Sales_Log!$N$5:$N$2004,Sales_Log!$S$5:$S$2004,$C$4,Sales_Log!$V$5:$V$2004,"Yes",Sales_Log!$F$5:$F$2004,$B35)) -> 0 | H35: =IF(OR($B35="",N(E35)=0),"",G35/E35) | J35: Vertical | K35: Sales | L35: Share % | M35: Gross Profit | N35: GM %
B36: =IF(Settings!$D$20="","",Settings!$D$20) -> Lighting Controls | C36: =IF($B36="","",SUMIFS(Sales_Log!$K$5:$K$2004,Sales_Log!$S$5:$S$2004,$C$4,Sales_Log!$V$5:$V$2004,"Yes",Sales_Log!$F$5:$F$2004,$B36,Sales_Log!$E$5:$E$2004,"Infrastructure")) -> 0 | D36: =IF($B36="","",SUMIFS(Sales_Log!$K$5:$K$2004,Sales_Log!$S$5:$S$2004,$C$4,Sales_Log!$V$5:$V$2004,"Yes",Sales_Log!$F$5:$F$2004,$B36,Sales_Log!$E$5:$E$2004,"Building")) -> 0 | E36: =IF($B36="","",N(C36)+N(D36)) -> 0 | F36: =IF(OR($B36="",$E$42=0),"",E36/$E$42) -> 0 | G36: =IF($B36="","",SUMIFS(Sales_Log!$N$5:$N$2004,Sales_Log!$S$5:$S$2004,$C$4,Sales_Log!$V$5:$V$2004,"Yes",Sales_Log!$F$5:$F$2004,$B36)) -> 0 | H36: =IF(OR($B36="",N(E36)=0),"",G36/E36) | J36: Infrastructure | K36: =C7 -> 21090 | L36: =IF($B$7=0,"",K36/$B$7) -> 1 | M36: =SUMIFS(Sales_Log!$N$5:$N$2004,Sales_Log!$S$5:$S$2004,$C$4,Sales_Log!$V$5:$V$2004,"Yes",Sales_Log!$E$5:$E$2004,J36) -> 6690 | N36: =IF(K36=0,"",M36/K36) -> 0.31721195
B37: =IF(Settings!$D$21="","",Settings!$D$21) -> Installation & Services | C37: =IF($B37="","",SUMIFS(Sales_Log!$K$5:$K$2004,Sales_Log!$S$5:$S$2004,$C$4,Sales_Log!$V$5:$V$2004,"Yes",Sales_Log!$F$5:$F$2004,$B37,Sales_Log!$E$5:$E$2004,"Infrastructure")) -> 0 | D37: =IF($B37="","",SUMIFS(Sales_Log!$K$5:$K$2004,Sales_Log!$S$5:$S$2004,$C$4,Sales_Log!$V$5:$V$2004,"Yes",Sales_Log!$F$5:$F$2004,$B37,Sales_Log!$E$5:$E$2004,"Building")) -> 0 | E37: =IF($B37="","",N(C37)+N(D37)) -> 0 | F37: =IF(OR($B37="",$E$42=0),"",E37/$E$42) -> 0 | G37: =IF($B37="","",SUMIFS(Sales_Log!$N$5:$N$2004,Sales_Log!$S$5:$S$2004,$C$4,Sales_Log!$V$5:$V$2004,"Yes",Sales_Log!$F$5:$F$2004,$B37)) -> 0 | H37: =IF(OR($B37="",N(E37)=0),"",G37/E37) | J37: Building | K37: =D7 -> 0 | L37: =IF($B$7=0,"",K37/$B$7) -> 0 | M37: =SUMIFS(Sales_Log!$N$5:$N$2004,Sales_Log!$S$5:$S$2004,$C$4,Sales_Log!$V$5:$V$2004,"Yes",Sales_Log!$E$5:$E$2004,J37) -> 0 | N37: =IF(K37=0,"",M37/K37)
B38: =IF(Settings!$D$22="","",Settings!$D$22) | C38: =IF($B38="","",SUMIFS(Sales_Log!$K$5:$K$2004,Sales_Log!$S$5:$S$2004,$C$4,Sales_Log!$V$5:$V$2004,"Yes",Sales_Log!$F$5:$F$2004,$B38,Sales_Log!$E$5:$E$2004,"Infrastructure")) | D38: =IF($B38="","",SUMIFS(Sales_Log!$K$5:$K$2004,Sales_Log!$S$5:$S$2004,$C$4,Sales_Log!$V$5:$V$2004,"Yes",Sales_Log!$F$5:$F$2004,$B38,Sales_Log!$E$5:$E$2004,"Building")) | E38: =IF($B38="","",N(C38)+N(D38)) | F38: =IF(OR($B38="",$E$42=0),"",E38/$E$42) | G38: =IF($B38="","",SUMIFS(Sales_Log!$N$5:$N$2004,Sales_Log!$S$5:$S$2004,$C$4,Sales_Log!$V$5:$V$2004,"Yes",Sales_Log!$F$5:$F$2004,$B38)) | H38: =IF(OR($B38="",N(E38)=0),"",G38/E38)
B39: =IF(Settings!$D$23="","",Settings!$D$23) | C39: =IF($B39="","",SUMIFS(Sales_Log!$K$5:$K$2004,Sales_Log!$S$5:$S$2004,$C$4,Sales_Log!$V$5:$V$2004,"Yes",Sales_Log!$F$5:$F$2004,$B39,Sales_Log!$E$5:$E$2004,"Infrastructure")) | D39: =IF($B39="","",SUMIFS(Sales_Log!$K$5:$K$2004,Sales_Log!$S$5:$S$2004,$C$4,Sales_Log!$V$5:$V$2004,"Yes",Sales_Log!$F$5:$F$2004,$B39,Sales_Log!$E$5:$E$2004,"Building")) | E39: =IF($B39="","",N(C39)+N(D39)) | F39: =IF(OR($B39="",$E$42=0),"",E39/$E$42) | G39: =IF($B39="","",SUMIFS(Sales_Log!$N$5:$N$2004,Sales_Log!$S$5:$S$2004,$C$4,Sales_Log!$V$5:$V$2004,"Yes",Sales_Log!$F$5:$F$2004,$B39)) | H39: =IF(OR($B39="",N(E39)=0),"",G39/E39)
B40: =IF(Settings!$D$24="","",Settings!$D$24) | C40: =IF($B40="","",SUMIFS(Sales_Log!$K$5:$K$2004,Sales_Log!$S$5:$S$2004,$C$4,Sales_Log!$V$5:$V$2004,"Yes",Sales_Log!$F$5:$F$2004,$B40,Sales_Log!$E$5:$E$2004,"Infrastructure")) | D40: =IF($B40="","",SUMIFS(Sales_Log!$K$5:$K$2004,Sales_Log!$S$5:$S$2004,$C$4,Sales_Log!$V$5:$V$2004,"Yes",Sales_Log!$F$5:$F$2004,$B40,Sales_Log!$E$5:$E$2004,"Building")) | E40: =IF($B40="","",N(C40)+N(D40)) | F40: =IF(OR($B40="",$E$42=0),"",E40/$E$42) | G40: =IF($B40="","",SUMIFS(Sales_Log!$N$5:$N$2004,Sales_Log!$S$5:$S$2004,$C$4,Sales_Log!$V$5:$V$2004,"Yes",Sales_Log!$F$5:$F$2004,$B40)) | H40: =IF(OR($B40="",N(E40)=0),"",G40/E40)
B41: =IF(Settings!$D$25="","",Settings!$D$25) | C41: =IF($B41="","",SUMIFS(Sales_Log!$K$5:$K$2004,Sales_Log!$S$5:$S$2004,$C$4,Sales_Log!$V$5:$V$2004,"Yes",Sales_Log!$F$5:$F$2004,$B41,Sales_Log!$E$5:$E$2004,"Infrastructure")) | D41: =IF($B41="","",SUMIFS(Sales_Log!$K$5:$K$2004,Sales_Log!$S$5:$S$2004,$C$4,Sales_Log!$V$5:$V$2004,"Yes",Sales_Log!$F$5:$F$2004,$B41,Sales_Log!$E$5:$E$2004,"Building")) | E41: =IF($B41="","",N(C41)+N(D41)) | F41: =IF(OR($B41="",$E$42=0),"",E41/$E$42) | G41: =IF($B41="","",SUMIFS(Sales_Log!$N$5:$N$2004,Sales_Log!$S$5:$S$2004,$C$4,Sales_Log!$V$5:$V$2004,"Yes",Sales_Log!$F$5:$F$2004,$B41)) | H41: =IF(OR($B41="",N(E41)=0),"",G41/E41)
B42: Total | C42: =SUM(C27:C41) -> 21090 | D42: =SUM(D27:D41) -> 0 | E42: =SUM(E27:E41) -> 21090 | F42: =IF(E42=0,"",1) -> 1 | G42: =SUM(G27:G41) -> 6690 | H42: =IF(E42=0,"",G42/E42) -> 0.31721195
B44: Sales Rep Performance
B45: Sales Rep | C45: Infrastructure | D45: Building | E45: Total Sales | F45: Gross Profit | G45: GM % | H45: Lines Won | I45: Open Pipeline
B46: =IF(Settings!$F$11="","",Settings!$F$11) -> Sales Rep 1 | C46: =IF($B46="","",SUMIFS(Sales_Log!$K$5:$K$2004,Sales_Log!$S$5:$S$2004,$C$4,Sales_Log!$V$5:$V$2004,"Yes",Sales_Log!$P$5:$P$2004,$B46,Sales_Log!$E$5:$E$2004,"Infrastructure")) -> 21090 | D46: =IF($B46="","",SUMIFS(Sales_Log!$K$5:$K$2004,Sales_Log!$S$5:$S$2004,$C$4,Sales_Log!$V$5:$V$2004,"Yes",Sales_Log!$P$5:$P$2004,$B46,Sales_Log!$E$5:$E$2004,"Building")) -> 0 | E46: =IF($B46="","",N(C46)+N(D46)) -> 21090 | F46: =IF($B46="","",SUMIFS(Sales_Log!$N$5:$N$2004,Sales_Log!$S$5:$S$2004,$C$4,Sales_Log!$V$5:$V$2004,"Yes",Sales_Log!$P$5:$P$2004,$B46)) -> 6690 | G46: =IF(OR($B46="",N(E46)=0),"",F46/E46) -> 0.31721195 | H46: =IF($B46="","",COUNTIFS(Sales_Log!$S$5:$S$2004,$C$4,Sales_Log!$V$5:$V$2004,"Yes",Sales_Log!$P$5:$P$2004,$B46)) -> 1 | I46: =IF($B46="","",SUMIFS(Sales_Log!$K$5:$K$2004,Sales_Log!$S$5:$S$2004,$C$4,Sales_Log!$W$5:$W$2004,"Yes",Sales_Log!$P$5:$P$2004,$B46)) -> 0
...

Sheet Settings
B2: Settings & Lists
B3: Edit the yellow cells. Lists feed the drop-downs in Sales_Log and the Dashboard tables.
B5: Currency label | C5: USD | D5: Shown on the Dashboard. Change to your currency (e.g. LKR, AED, INR).
B6: Fiscal year start month (1-12) | C6: 1 | D6: 1 = January. Use 4 for an April-March financial year.
B7: Department | C7: Lighting Solutions | D7: Shown in the Dashboard title.
B10: Business Verticals | D10: Product Categories | F10: Sales Reps | H10: Status | I10: Counts as Sale? | J10: Counts as Pipeline?
B11: Infrastructure | D11: Street Lighting | F11: Sales Rep 1 | H11: Quotation | I11: No | J11: Yes
B12: Building | D12: Floodlighting | F12: Sales Rep 2 | H12: Order Confirmed | I12: No | J12: Yes
B13: Verticals are fixed - the Dashboard is built around these two. | D13: High Mast | F13: Sales Rep 3 | H13: Invoiced | I13: Yes | J13: No
D14: Tunnel Lighting | F14: Sales Rep 4 | H14: Paid | I14: Yes | J14: No
D15: Solar Lighting | F15: Sales Rep 5 | H15: Lost | I15: No | J15: No
D16: Indoor Commercial
D17: Industrial / High Bay
D18: Architectural / Facade
D19: Emergency & Exit
D20: Lighting Controls
D21: Installation & Services
D27: Up to 15 categories / reps. Add new ones in the next empty yellow cell.

Sheet Sales_Log
A1: Sales Log
A2: Enter one row per invoice / order line. Yellow = input, grey = automatic. Row 5 is an EXAMPLE - overwrite it with your first real entry.
J3: Filtered total: | K3: =SUBTOTAL(9,K5:K2004) -> 21090 | N3: =SUBTOTAL(9,N5:N2004) -> 6690
A4: Date | B4: Invoice / Ref No | C4: Customer | D4: Project / Site | E4: Vertical | F4: Product Category | G4: Description | H4: Qty | I4: Unit Price | J4: Discount % | K4: Net Sales | L4: Unit Cost | M4: Total Cost | N4: Gross Profit | O4: GM % | P4: Sales Rep | Q4: Status | R4: Notes | S4: FY | T4: FY Period | U4: Month | V4: Sale? | W4: Pipeline?
A5: 46280 | B5: INV-0001 | C5: Example Contractors Ltd | D5: Highway Stretch A | E5: Infrastructure | F5: Street Lighting | G5: 150W LED street light | H5: 120 | I5: 185 | J5: 0.05 | K5: =IF(OR(H5="",I5=""),"",H5*I5*(1-N(J5))) -> 21090 | L5: 120 | M5: =IF(OR(H5="",L5=""),"",H5*L5) -> 14400 | N5: =IF(OR(K5="",M5=""),"",K5-M5) -> 6690 | O5: =IF(OR(N5="",K5=""),"",IF(K5=0,"",N5/K5)) -> 0.31721195 | P5: Sales Rep 1 | Q5: Invoiced | R5: EXAMPLE - replace with real data | S5: =IF(A5="","",YEAR(A5)+IF(AND(FYStart>1,MONTH(A5)>=FYStart),1,0)) -> 2026 | T5: =IF(A5="","",MOD(MONTH(A5)-FYStart,12)+1) -> 9 | U5: =IF(A5="","",TEXT(A5,"mmm")) -> Sep | V5: =IF(Q5="","",IFERROR(INDEX(Settings!$I$11:$I$15,MATCH(Q5,Settings!$H$11:$H$15,0)),"No")) -> Yes | W5: =IF(Q5="","",IFERROR(INDEX(Settings!$J$11:$J$15,MATCH(Q5,Settings!$H$11:$H$15,0)),"No")) -> No
K6: =IF(OR(H6="",I6=""),"",H6*I6*(1-N(J6))) | M6: =IF(OR(H6="",L6=""),"",H6*L6) | N6: =IF(OR(K6="",M6=""),"",K6-M6) | O6: =IF(OR(N6="",K6=""),"",IF(K6=0,"",N6/K6)) | S6: =IF(A6="","",YEAR(A6)+IF(AND(FYStart>1,MONTH(A6)>=FYStart),1,0)) | T6: =IF(A6="","",MOD(MONTH(A6)-FYStart,12)+1) | U6: =IF(A6="","",TEXT(A6,"mmm")) | V6: =IF(Q6="","",IFERROR(INDEX(Settings!$I$11:$I$15,MATCH(Q6,Settings!$H$11:$H$15,0)),"No")) | W6: =IF(Q6="","",IFERROR(INDEX(Settings!$J$11:$J$15,MATCH(Q6,Settings!$H$11:$H$15,0)),"No"))
K7: =IF(OR(H7="",I7=""),"",H7*I7*(1-N(J7))) | M7: =IF(OR(H7="",L7=""),"",H7*L7) | N7: =IF(OR(K7="",M7=""),"",K7-M7) | O7: =IF(OR(N7="",K7=""),"",IF(K7=0,"",N7/K7)) | S7: =IF(A7="","",YEAR(A7)+IF(AND(FYStart>1,MONTH(A7)>=FYStart),1,0)) | T7: =IF(A7="","",MOD(MONTH(A7)-FYStart,12)+1) | U7: =IF(A7="","",TEXT(A7,"mmm")) | V7: =IF(Q7="","",IFERROR(INDEX(Settings!$I$11:$I$15,MATCH(Q7,Settings!$H$11:$H$15,0)),"No")) | W7: =IF(Q7="","",IFERROR(INDEX(Settings!$J$11:$J$15,MATCH(Q7,Settings!$H$11:$H$15,0)),"No"))
K8: =IF(OR(H8="",I8=""),"",H8*I8*(1-N(J8))) | M8: =IF(OR(H8="",L8=""),"",H8*L8) | N8: =IF(OR(K8="",M8=""),"",K8-M8) | O8: =IF(OR(N8="",K8=""),"",IF(K8=0,"",N8/K8)) | S8: =IF(A8="","",YEAR(A8)+IF(AND(FYStart>1,MONTH(A8)>=FYStart),1,0)) | T8: =IF(A8="","",MOD(MONTH(A8)-FYStart,12)+1) | U8: =IF(A8="","",TEXT(A8,"mmm")) | V8: =IF(Q8="","",IFERROR(INDEX(Settings!$I$11:$I$15,MATCH(Q8,Settings!$H$11:$H$15,0)),"No")) | W8: =IF(Q8="","",IFERROR(INDEX(Settings!$J$11:$J$15,MATCH(Q8,Settings!$H$11:$H$15,0)),"No"))
K9: =IF(OR(H9="",I9=""),"",H9*I9*(1-N(J9))) | M9: =IF(OR(H9="",L9=""),"",H9*L9) | N9: =IF(OR(K9="",M9=""),"",K9-M9) | O9: =IF(OR(N9="",K9=""),"",IF(K9=0,"",N9/K9)) | S9: =IF(A9="","",YEAR(A9)+IF(AND(FYStart>1,MONTH(A9)>=FYStart),1,0)) | T9: =IF(A9="","",MOD(MONTH(A9)-FYStart,12)+1) | U9: =IF(A9="","",TEXT(A9,"mmm")) | V9: =IF(Q9="","",IFERROR(INDEX(Settings!$I$11:$I$15,MATCH(Q9,Settings!$H$11:$H$15,0)),"No")) | W9: =IF(Q9="","",IFERROR(INDEX(Settings!$J$11:$J$15,MATCH(Q9,Settings!$H$11:$H$15,0)),"No"))
K10: =IF(OR(H10="",I10=""),"",H10*I10*(1-N(J10))) | M10: =IF(OR(H10="",L10=""),"",H10*L10) | N10: =IF(OR(K10="",M10=""),"",K10-M10) | O10: =IF(OR(N10="",K10=""),"",IF(K10=0,"",N10/K10)) | S10: =IF(A10="","",YEAR(A10)+IF(AND(FYStart>1,MONTH(A10)>=FYStart),1,0)) | T10: =IF(A10="","",MOD(MONTH(A10)-FYStart,12)+1) | U10: =IF(A10="","",TEXT(A10,"mmm")) | V10: =IF(Q10="","",IFERROR(INDEX(Settings!$I$11:$I$15,MATCH(Q10,Settings!$H$11:$H$15,0)),"No")) | W10: =IF(Q10="","",IFERROR(INDEX(Settings!$J$11:$J$15,MATCH(Q10,Settings!$H$11:$H$15,0)),"No"))
K11: =IF(OR(H11="",I11=""),"",H11*I11*(1-N(J11))) | M11: =IF(OR(H11="",L11=""),"",H11*L11) | N11: =IF(OR(K11="",M11=""),"",K11-M11) | O11: =IF(OR(N11="",K11=""),"",IF(K11=0,"",N11/K11)) | S11: =IF(A11="","",YEAR(A11)+IF(AND(FYStart>1,MONTH(A11)>=FYStart),1,0)) | T11: =IF(A11="","",MOD(MONTH(A11)-FYStart,12)+1) | U11: =IF(A11="","",TEXT(A11,"mmm")) | V11: =IF(Q11="","",IFERROR(INDEX(Settings!$I$11:$I$15,MATCH(Q11,Settings!$H$11:$H$15,0)),"No")) | W11: =IF(Q11="","",IFERROR(INDEX(Settings!$J$11:$J$15,MATCH(Q11,Settings!$H$11:$H$15,0)),"No"))
K12: =IF(OR(H12="",I12=""),"",H12*I12*(1-N(J12))) | M12: =IF(OR(H12="",L12=""),"",H12*L12) | N12: =IF(OR(K12="",M12=""),"",K12-M12) | O12: =IF(OR(N12="",K12=""),"",IF(K12=0,"",N12/K12)) | S12: =IF(A12="","",YEAR(A12)+IF(AND(FYStart>1,MONTH(A12)>=FYStart),1,0)) | T12: =IF(A12="","",MOD(MONTH(A12)-FYStart,12)+1) | U12: =IF(A12="","",TEXT(A12,"mmm")) | V12: =IF(Q12="","",IFERROR(INDEX(Settings!$I$11:$I$15,MATCH(Q12,Settings!$H$11:$H$15,0)),"No")) | W12: =IF(Q12="","",IFERROR(INDEX(Settings!$J$11:$J$15,MATCH(Q12,Settings!$H$11:$H$15,0)),"No"))
K13: =IF(OR(H13="",I13=""),"",H13*I13*(1-N(J13))) | M13: =IF(OR(H13="",L13=""),"",H13*L13) | N13: =IF(OR(K13="",M13=""),"",K13-M13) | O13: =IF(OR(N13="",K13=""),"",IF(K13=0,"",N13/K13)) | S13: =IF(A13="","",YEAR(A13)+IF(AND(FYStart>1,MONTH(A13)>=FYStart),1,0)) | T13: =IF(A13="","",MOD(MONTH(A13)-FYStart,12)+1) | U13: =IF(A13="","",TEXT(A13,"mmm")) | V13: =IF(Q13="","",IFERROR(INDEX(Settings!$I$11:$I$15,MATCH(Q13,Settings!$H$11:$H$15,0)),"No")) | W13: =IF(Q13="","",IFERROR(INDEX(Settings!$J$11:$J$15,MATCH(Q13,Settings!$H$11:$H$15,0)),"No"))
K14: =IF(OR(H14="",I14=""),"",H14*I14*(1-N(J14))) | M14: =IF(OR(H14="",L14=""),"",H14*L14) | N14: =IF(OR(K14="",M14=""),"",K14-M14) | O14: =IF(OR(N14="",K14=""),"",IF(K14=0,"",N14/K14)) | S14: =IF(A14="","",YEAR(A14)+IF(AND(FYStart>1,MONTH(A14)>=FYStart),1,0)) | T14: =IF(A14="","",MOD(MONTH(A14)-FYStart,12)+1) | U14: =IF(A14="","",TEXT(A14,"mmm")) | V14: =IF(Q14="","",IFERROR(INDEX(Settings!$I$11:$I$15,MATCH(Q14,Settings!$H$11:$H$15,0)),"No")) | W14: =IF(Q14="","",IFERROR(INDEX(Settings!$J$11:$J$15,MATCH(Q14,Settings!$H$11:$H$15,0)),"No"))
K15: =IF(OR(H15="",I15=""),"",H15*I15*(1-N(J15))) | M15: =IF(OR(H15="",L15=""),"",H15*L15) | N15: =IF(OR(K15="",M15=""),"",K15-M15) | O15: =IF(OR(N15="",K15=""),"",IF(K15=0,"",N15/K15)) | S15: =IF(A15="","",YEAR(A15)+IF(AND(FYStart>1,MONTH(A15)>=FYStart),1,0)) | T15: =IF(A15="","",MOD(MONTH(A15)-FYStart,12)+1) | U15: =IF(A15="","",TEXT(A15,"mmm")) | V15: =IF(Q15="","",IFERROR(INDEX(Settings!$I$11:$I$15,MATCH(Q15,Settings!$H$11:$H$15,0)),"No")) | W15: =IF(Q15="","",IFERROR(INDEX(Settings!$J$11:$J$15,MATCH(Q15,Settings!$H$11:$H$15,0)),"No"))
K16: =IF(OR(H16="",I16=""),"",H16*I16*(1-N(J16))) | M16: =IF(OR(H16="",L16=""),"",H16*L16) | N16: =IF(OR(K16="",M16=""),"",K16-M16) | O16: =IF(OR(N16="",K16=""),"",IF(K16=0,"",N16/K16)) | S16: =IF(A16="","",YEAR(A16)+IF(AND(FYStart>1,MONTH(A16)>=FYStart),1,0)) | T16: =IF(A16="","",MOD(MONTH(A16)-FYStart,12)+1) | U16: =IF(A16="","",TEXT(A16,"mmm")) | V16: =IF(Q16="","",IFERROR(INDEX(Settings!$I$11:$I$15,MATCH(Q16,Settings!$H$11:$H$15,0)),"No")) | W16: =IF(Q16="","",IFERROR(INDEX(Settings!$J$11:$J$15,MATCH(Q16,Settings!$H$11:$H$15,0)),"No"))
K17: =IF(OR(H17="",I17=""),"",H17*I17*(1-N(J17))) | M17: =IF(OR(H17="",L17=""),"",H17*L17) | N17: =IF(OR(K17="",M17=""),"",K17-M17) | O17: =IF(OR(N17="",K17=""),"",IF(K17=0,"",N17/K17)) | S17: =IF(A17="","",YEAR(A17)+IF(AND(FYStart>1,MONTH(A17)>=FYStart),1,0)) | T17: =IF(A17="","",MOD(MONTH(A17)-FYStart,12)+1) | U17: =IF(A17="","",TEXT(A17,"mmm")) | V17: =IF(Q17="","",IFERROR(INDEX(Settings!$I$11:$I$15,MATCH(Q17,Settings!$H$11:$H$15,0)),"No")) | W17: =IF(Q17="","",IFERROR(INDEX(Settings!$J$11:$J$15,MATCH(Q17,Settings!$H$11:$H$15,0)),"No"))
... K2004: =IF(OR(H2004="",I2004=""),"",H2004*I2004*(1-N(J2004))) | M2004: =IF(OR(H2004="",L2004=""),"",H2004*L2004) | N2004: =IF(OR(K2004="",M2004=""),"",K2004-M2004) | O2004: =IF(OR(N2004="",K2004=""),"",IF(K2004=0,"",N2004/K2004)) | S2004: =IF(A2004="","",YEAR(A2004)+IF(AND(FYStart>1,MONTH(A2004)>=FYStart),1,0)) | T2004: =IF(A2004="","",MOD(MONTH(A2004)-FYStart,12)+1) | U2004: =IF(A2004="","",TEXT(A2004,"mmm")) | V2004: =IF(Q2004="","",IFERROR(INDEX(Settings!$I$11:$I$15,MATCH(Q2004,Settings!$H$11:$H$15,0)),"No")) | W2004: =IF(Q2004="","",IFERROR(INDEX(Settings!$J$11:$J$15,MATCH(Q2004,Settings!$H$11:$H$15,0)),"No"))

Sheet Targets
B2: Monthly Sales Targets
B3: Enter targets per vertical in the yellow cells (amounts in your Settings currency, excluding tax).
B5: FY | C5: Period | D5: Month | E5: Infrastructure Target | F5: Building Target | G5: Total Target | I5: To add another year: copy a 13-row block, paste below, and change the FY number.
B6: 2026 | C6: 1 | D6: =TEXT(DATE(2000,FYStart+C6-1,1),"mmm") -> Jan | G6: =N(E6)+N(F6) -> 0
B7: 2026 | C7: 2 | D7: =TEXT(DATE(2000,FYStart+C7-1,1),"mmm") -> Feb | G7: =N(E7)+N(F7) -> 0
B8: 2026 | C8: 3 | D8: =TEXT(DATE(2000,FYStart+C8-1,1),"mmm") -> Mar | G8: =N(E8)+N(F8) -> 0
B9: 2026 | C9: 4 | D9: =TEXT(DATE(2000,FYStart+C9-1,1),"mmm") -> Apr | G9: =N(E9)+N(F9) -> 0
B10: 2026 | C10: 5 | D10: =TEXT(DATE(2000,FYStart+C10-1,1),"mmm") -> May | G10: =N(E10)+N(F10) -> 0
B11: 2026 | C11: 6 | D11: =TEXT(DATE(2000,FYStart+C11-1,1),"mmm") -> Jun | G11: =N(E11)+N(F11) -> 0
B12: 2026 | C12: 7 | D12: =TEXT(DATE(2000,FYStart+C12-1,1),"mmm") -> Jul | G12: =N(E12)+N(F12) -> 0
B13: 2026 | C13: 8 | D13: =TEXT(DATE(2000,FYStart+C13-1,1),"mmm") -> Aug | G13: =N(E13)+N(F13) -> 0
B14: 2026 | C14: 9 | D14: =TEXT(DATE(2000,FYStart+C14-1,1),"mmm") -> Sep | G14: =N(E14)+N(F14) -> 0
B15: 2026 | C15: 10 | D15: =TEXT(DATE(2000,FYStart+C15-1,1),"mmm") -> Oct | G15: =N(E15)+N(F15) -> 0
B16: 2026 | C16: 11 | D16: =TEXT(DATE(2000,FYStart+C16-1,1),"mmm") -> Nov | G16: =N(E16)+N(F16) -> 0
B17: 2026 | C17: 12 | D17: =TEXT(DATE(2000,FYStart+C17-1,1),"mmm") -> Dec | G17: =N(E17)+N(F17) -> 0
B18: 2026 | C18: Total | E18: =SUM(E6:E17) -> 0 | F18: =SUM(F6:F17) -> 0 | G18: =SUM(G6:G17) -> 0
B20: 2027 | C20: 1 | D20: =TEXT(DATE(2000,FYStart+C20-1,1),"mmm") -> Jan | G20: =N(E20)+N(F20) -> 0
B21: 2027 | C21: 2 | D21: =TEXT(DATE(2000,FYStart+C21-1,1),"mmm") -> Feb | G21: =N(E21)+N(F21) -> 0
B22: 2027 | C22: 3 | D22: =TEXT(DATE(2000,FYStart+C22-1,1),"mmm") -> Mar | G22: =N(E22)+N(F22) -> 0
B23: 2027 | C23: 4 | D23: =TEXT(DATE(2000,FYStart+C23-1,1),"mmm") -> Apr | G23: =N(E23)+N(F23) -> 0
B24: 2027 | C24: 5 | D24: =TEXT(DATE(2000,FYStart+C24-1,1),"mmm") -> May | G24: =N(E24)+N(F24) -> 0
B25: 2027 | C25: 6 | D25: =TEXT(DATE(2000,FYStart+C25-1,1),"mmm") -> Jun | G25: =N(E25)+N(F25) -> 0
B26: 2027 | C26: 7 | D26: =TEXT(DATE(2000,FYStart+C26-1,1),"mmm") -> Jul | G26: =N(E26)+N(F26) -> 0
B27: 2027 | C27: 8 | D27: =TEXT(DATE(2000,FYStart+C27-1,1),"mmm") -> Aug | G27: =N(E27)+N(F27) -> 0
B28: 2027 | C28: 9 | D28: =TEXT(DATE(2000,FYStart+C28-1,1),"mmm") -> Sep | G28: =N(E28)+N(F28) -> 0
B29: 2027 | C29: 10 | D29: =TEXT(DATE(2000,FYStart+C29-1,1),"mmm") -> Oct | G29: =N(E29)+N(F29) -> 0
B30: 2027 | C30: 11 | D30: =TEXT(DATE(2000,FYStart+C30-1,1),"mmm") -> Nov | G30: =N(E30)+N(F30) -> 0
B31: 2027 | C31: 12 | D31: =TEXT(DATE(2000,FYStart+C31-1,1),"mmm") -> Dec | G31: =N(E31)+N(F31) -> 0
B32: 2027 | C32: Total | E32: =SUM(E20:E31) -> 0 | F32: =SUM(F20:F31) -> 0 | G32: =SUM(G20:G31) -> 0
B34: 2028 | C34: 1 | D34: =TEXT(DATE(2000,FYStart+C34-1,1),"mmm") -> Jan | G34: =N(E34)+N(F34) -> 0
B35: 2028 | C35: 2 | D35: =TEXT(DATE(2000,FYStart+C35-1,1),"mmm") -> Feb | G35: =N(E35)+N(F35) -> 0
B36: 2028 | C36: 3 | D36: =TEXT(DATE(2000,FYStart+C36-1,1),"mmm") -> Mar | G36: =N(E36)+N(F36) -> 0
B37: 2028 | C37: 4 | D37: =TEXT(DATE(2000,FYStart+C37-1,1),"mmm") -> Apr | G37: =N(E37)+N(F37) -> 0
B38: 2028 | C38: 5 | D38: =TEXT(DATE(2000,FYStart+C38-1,1),"mmm") -> May | G38: =N(E38)+N(F38) -> 0
B39: 2028 | C39: 6 | D39: =TEXT(DATE(2000,FYStart+C39-1,1),"mmm") -> Jun | G39: =N(E39)+N(F39) -> 0
B40: 2028 | C40: 7 | D40: =TEXT(DATE(2000,FYStart+C40-1,1),"mmm") -> Jul | G40: =N(E40)+N(F40) -> 0
B41: 2028 | C41: 8 | D41: =TEXT(DATE(2000,FYStart+C41-1,1),"mmm") -> Aug | G41: =N(E41)+N(F41) -> 0
B42: 2028 | C42: 9 | D42: =TEXT(DATE(2000,FYStart+C42-1,1),"mmm") -> Sep | G42: =N(E42)+N(F42) -> 0
B43: 2028 | C43: 10 | D43: =TEXT(DATE(2000,FYStart+C43-1,1),"mmm") -> Oct | G43: =N(E43)+N(F43) -> 0
B44: 2028 | C44: 11 | D44: =TEXT(DATE(2000,FYStart+C44-1,1),"mmm") -> Nov | G44: =N(E44)+N(F44) -> 0
...
